<?xml version="1.0" ?>
<robot name="widowx_arm" xmlns:xacro="http://ros.org/wiki/xacro">

	<xacro:include filename="$(find widowx_arm_description)/urdf/common_materials.xacro" />

	<!-- base_link -->
	<link name="base_footprint">
		<visual>
			<origin xyz="0 0 0" rpy="0 0 0"/>
			<geometry>
				<box size="0.001 0.001 0.001" />
			</geometry>
		</visual>
	</link>

	<!-- arm_base_link -->
	<joint name="arm_base_joint" type="fixed">
		<origin xyz="0 0 0" rpy="0 0 0" />
		<parent link="base_footprint" />
		<child link="arm_base_link"/>
	</joint>
	<link name="arm_base_link">
		<visual>
			<origin xyz="0 0 0" rpy="0 0 0" />
			<geometry>
				<mesh filename="package://widowx_arm_description/meshes/base_link.stl"/>
			</geometry>
			<xacro:material_black />
		</visual>
		<collision>
			<origin xyz="0 0 0" rpy="0 0 0" />
			<geometry>
				<mesh filename="package://widowx_arm_description/meshes/base_link.stl"/>
			</geometry>
		</collision>
		<inertial>
			<origin xyz="0 0 0" rpy="0 0 0" />
			<mass value="1" />
			<inertia ixx="1.0" ixy="0.0" ixz="0.0" iyy="1.0" iyz="0.0" izz="1.0" />
		</inertial>
	</link>

	<!-- shoulder_link -->
	<joint name="joint_1" type="revolute">
		<origin xyz="0 0 0.125" rpy="0 0 0" />
		<parent link="arm_base_link" />
		<child link="shoulder_link" />
		<axis xyz="0 0 1" />
		<limit lower="-2.617" upper="2.617" effort="6" velocity="0.785" />
	</joint>
	<link name="shoulder_link">
		<visual>
			<origin xyz="0 0 0" rpy="0 0 0" />
			<geometry>
				<mesh filename="package://widowx_arm_description/meshes/shoulder_link.stl" />
			</geometry>
			<xacro:material_black />
		</visual>
		<collision>
			<origin xyz="0 0 0" rpy="0 0 0" />
			<geometry>
				<mesh filename="package://widowx_arm_description/meshes/shoulder_link.stl"/>
			</geometry>
		</collision>
		<inertial>
			<origin xyz="0 0 0" rpy="0 0 0" />
			<mass value="1" />
			<inertia ixx="1.0" ixy="0.0" ixz="0.0" iyy="1.0" iyz="0.0" izz="1.0" />
		</inertial>
	</link>
	<transmission name="tran1">
		<type>transmission_interface/SimpleTransmission</type>
		<joint name="joint_1"/>
		<actuator name="motor1">
			<hardwareInterface>EffortJointInterface</hardwareInterface>
			<mechanicalReduction>1</mechanicalReduction>
		</actuator>
	</transmission>

	<!-- biceps_link -->
	<joint name="joint_2" type="revolute">
		<!--origin xyz="0.04825 0 0.14203" rpy="0 0 0" /-->
		<origin xyz="0 0 0" rpy="0 0 0" />
		<parent link="shoulder_link" />
		<child link="biceps_link" />
		<axis xyz="0 1 0" />
		<limit lower="-1.571" upper="1.571" effort="6" velocity="1.571" />
	</joint>
	<link name="biceps_link">
		<visual>
			<origin xyz="0 0 0" rpy="0 0 0" />
			<geometry>
				<mesh filename="package://widowx_arm_description/meshes/biceps_link.new.stl" />
			</geometry>
			<xacro:material_black />
		</visual>
		<collision>
			<origin xyz="0 0 0" rpy="0 0 0" />
			<geometry>
				<mesh filename="package://widowx_arm_description/meshes/biceps_link.new.stl" />
			</geometry>
		</collision>
		<inertial>
			<origin xyz="0 0 0" rpy="0 0 0" />
			<mass value="1" />
			<inertia ixx="1.0" ixy="0.0" ixz="0.0" iyy="1.0" iyz="0.0" izz="1.0" />
		</inertial>
	</link>
	<transmission name="tran2">
		<type>transmission_interface/SimpleTransmission</type>
		<joint name="joint_2"/>
		<actuator name="motor2">
			<hardwareInterface>EffortJointInterface</hardwareInterface>
			<mechanicalReduction>1</mechanicalReduction>
		</actuator>
	 </transmission>

	<!-- forearm_link -->
	<joint name="joint_3" type="revolute">
		<origin xyz="0.04825 0 0.14203" rpy="0 1.570795 0" />
		<parent link="biceps_link" />
		<child link="forearm_link" />
		<axis xyz="0 1 0" />
		<limit lower="-1.571" upper="1.571" effort="6" velocity="1.571" />
	</joint>
	<link name="forearm_link">
		<visual>
			<origin xyz="0 0 0" rpy="0 0 0" />
			<geometry>
				<mesh filename="package://widowx_arm_description/meshes/forearm_link.new.stl"/>
			</geometry>
			<xacro:material_black />
		</visual>
		<collision>
			<origin xyz="0 0 0" rpy="0 0 0" />
			<geometry>
				<mesh filename="package://widowx_arm_description/meshes/forearm_link.new.stl"/>
			</geometry>
		</collision>
		<inertial>
			<origin xyz="0 0 0" rpy="0 0 0" />
			<mass value="1" />
			<inertia ixx="1.0" ixy="0.0" ixz="0.0" iyy="1.0" iyz="0.0" izz="1.0"/>
		</inertial>
	</link>
	<transmission name="tran3">
		<type>transmission_interface/SimpleTransmission</type>
		<joint name="joint_3"/>
		<actuator name="motor3">
			<hardwareInterface>EffortJointInterface</hardwareInterface>
			<mechanicalReduction>1</mechanicalReduction>
		</actuator>
	</transmission>

	<!-- wrist_1_link -->
	<joint name="joint_4" type="revolute">
		<origin xyz="0 0 0.14203" rpy="0 0 0" />
		<parent link="forearm_link" />
		<child link="wrist_1_link" />
		<axis xyz="0 1 0" />
		<limit lower="-1.745" upper="1.745" effort="6" velocity="1.571" />
	</joint>
	<link name="wrist_1_link">
		<visual>
			<origin xyz="0 0 0" rpy="0 0 0" />
			<geometry>
				<mesh filename="package://widowx_arm_description/meshes/wrist_1_link.stl"/>
			</geometry>
			<xacro:material_black />
		</visual>
		<collision>
			<origin xyz="0 0 0" rpy="0 0 0" />
			<geometry>
				<mesh filename="package://widowx_arm_description/meshes/wrist_1_link.stl"/>
			</geometry>
		</collision>
		<inertial>
			<origin xyz="0 0 0" rpy="0 0 0" />
			<mass value="1" />
			<inertia ixx="1.0" ixy="0.0" ixz="0.0" iyy="1.0" iyz="0.0" izz="1.0" />
		</inertial>
	</link>
	<transmission name="tran4">
		<type>transmission_interface/SimpleTransmission</type>
		<joint name="joint_4"/>
		<actuator name="motor4">
			<hardwareInterface>EffortJointInterface</hardwareInterface>
			<mechanicalReduction>1</mechanicalReduction>
		</actuator>
	</transmission>

	<!-- wrist_2_link -->
	<joint name="joint_5" type="revolute">
		<origin xyz="0 0 0.0715" rpy="0 0 0" />
		<parent link="wrist_1_link" />
		<child link="wrist_2_link" />
		<axis xyz="0 0 1" />
		<limit lower="-2.617" upper="2.617" effort="6" velocity="1.571" />
	</joint>
	<link name="wrist_2_link">
		<visual>
			<origin xyz="0 0 0" rpy="0 0 0" />
			<geometry>
				<mesh filename="package://widowx_arm_description/meshes/wrist_2_link.new.stl"/>
			</geometry>
			<xacro:material_black />
		</visual>
		<collision>
			<origin xyz="0 0 0" rpy="0 0 0" />
			<geometry>
				<mesh filename="package://widowx_arm_description/meshes/wrist_2_link.new.stl"/>
			</geometry>
		</collision>
		<inertial>
			<origin xyz="0 0 0" rpy="0 0 0" />
			<mass value="1" />
			<inertia ixx="1.0" ixy="0.0" ixz="0.0" iyy="1.0" iyz="0.0" izz="1.0" />
		</inertial>
	</link>
	<transmission name="tran5">
		<type>transmission_interface/SimpleTransmission</type>
		<joint name="joint_5"/>
		<actuator name="motor5">
			<hardwareInterface>EffortJointInterface</hardwareInterface>
			<mechanicalReduction>1</mechanicalReduction>
		</actuator>
	</transmission>

	<!-- gripper -->
	<xacro:include filename="$(find widowx_arm_description)/urdf/widowx_gripper.xacro"/>

</robot>
